<?xml version="1.0"?>
<!--
  GOAT Robot URDF — Version 3 (Elliptical, 2 Segments Per Ring)
  
  REDESIGN: Circuit topology with 4 segments connecting 4 corner wheels
  Structure: 2 rings (Z=0 and Z=0.10), each with 4 segments forming rectangular circuit
  Segments: Front (FL→FR), Right (FR→RR), Back (RR→RL), Left (RL→FL)
  Wheels at 4 corners: FL, FR, RL, RR (front-left, front-right, rear-left, rear-right)

 
  ROBOT SPECIFICATIONS FROM PAPER
  
  GEOMETRY:
    • Elliptical structure with 2 stacked rings (Z separation = 0.10 m)
    • Each ring: 2 long parallel segments connected at 4 corners via lenses
    • Segment length (front-rear): 0.70 m (L_FR axis)
    • Segment separation (left-right): 0.50 m (L_LR axis)
    • Thus wheel positions form rectangle: ±0.25 m (X), ±0.35 m (Y)
    
  WHEELS:
    • 4 rimless wheels, positioned at rectangle corners
    • FL (Front-Left):   (+0.30, +0.35, z_lens)  → Y-axis spin
    • FR (Front-Right):  (+0.30, -0.35, z_lens)  → X-axis spin
    • RL (Rear-Left):    (-0.30, +0.35, z_lens)  → Y-axis spin
    • RR (Rear-Right):   (-0.30, -0.35, z_lens)  → X-axis spin
    • Spoke radius: 0.25 m (matches full X width when circles touch)
    • Mass per wheel: 0.05 kg
  
  FRAME (Circuit topology):
    • Front segment (Z varies): Connects FL lens to FR lens (0.60m, ~0.08 kg)
    • Right segment: Connects FR lens to RR lens (0.70m, ~0.10 kg)
    • Back segment: Connects RR lens to RL lens (0.60m, ~0.08 kg)
    • Left segment: Connects RL lens toward FL lens (0.70m, ~0.10 kg, closes loop via tendons)
    • Segment diameter: 5 mm fiberglass
    • 2 orthogonal tendons control circuit morphing (deformation)
  
  CONNECTORS (Lenses × 4):
    • Fixed rigid joints at wheel mounting points
    • Connect both rings at same XY location (form "lens" structures)
    • FL lens @ (+0.30, +0.35, 0.05)
    • FR lens @ (+0.30, -0.35, 0.05)
    • RL lens @ (-0.30, +0.35, 0.05)
    • RR lens @ (-0.30, -0.35, 0.05)
  
  MASS DISTRIBUTION:
    • Total: 2.8 kg
    • Payload: 1.8 kg
    • Segments (Front+Right+Back+Left, 2 rings each): ~0.36 kg
    • Wheels (4×0.05kg): 0.2 kg
    • Lenses (4×0.01kg): 0.04 kg
    • Tendons (2×): ~0.4 kg (not modeled, estimated from paper)
  
-->
<robot name="goat">

  <material name="fiberglass"><color rgba="0.95 0.85 0.10 1.0"/></material>
  <material name="payload_box"><color rgba="0.10 0.35 0.70 1.0"/></material>
  <material name="wheel_dark"><color rgba="0.12 0.12 0.12 1.0"/></material>
  <material name="connector"><color rgba="0.80 0.30 0.10 1.0"/></material>

  <!-- PAYLOAD — base link, 1.8 kg -->
  <link name="payload">
    <visual>
      <origin xyz="0 0 0" rpy="0 0 0"/>
      <geometry><box size="0.20 0.14 0.08"/></geometry>
      <material name="payload_box"/>
    </visual>
    <collision>
      <origin xyz="0 0 0" rpy="0 0 0"/>
      <geometry><box size="0.20 0.14 0.08"/></geometry>
    </collision>
    <inertial>
      <origin xyz="0 0 0" rpy="0 0 0"/>
      <mass value="1.80"/>
      <inertia ixx="0.003940" ixy="0" ixz="0"
               iyy="0.005150" iyz="0"
               izz="0.006720"/>
    </inertial>
  </link>

  <!-- 
       LENSES (Lens Connectors ×4) — Rigid mounts at wheel positions
       
       Fixed joints at the 4 corners rigidly couple wheel attachment points.
       FL lens @ (+0.30, +0.35, 0.05): front-left
       FR lens @ (+0.30, -0.35, 0.05): front-right
       RL lens @ (-0.30, +0.35, 0.05): rear-left
       RR lens @ (-0.30, -0.35, 0.05): rear-right
 -->

  <link name="lens_FL">
    <visual>
      <origin xyz="0 0 0" rpy="0 0 0"/>
      <geometry><box size="0.08 0.08 0.02"/></geometry>
      <material name="connector"/>
    </visual>
    <collision>
      <origin xyz="0 0 0" rpy="0 0 0"/>
      <geometry><box size="0.08 0.08 0.02"/></geometry>
    </collision>
    <inertial>
      <origin xyz="0 0 0" rpy="0 0 0"/>
      <mass value="0.010"/>
      <inertia ixx="0.000011" ixy="0" ixz="0"
               iyy="0.000011" iyz="0"
               izz="0.000011"/>
    </inertial>
  </link>
  <joint name="lens_FL_joint" type="fixed">
    <parent link="payload"/>
    <child  link="lens_FL"/>
    <origin xyz="0.30 0.35 0.05" rpy="0 0 0"/>
  </joint>

  <link name="lens_FR">
    <visual>
      <origin xyz="0 0 0" rpy="0 0 0"/>
      <geometry><box size="0.08 0.08 0.02"/></geometry>
      <material name="connector"/>
    </visual>
    <collision>
      <origin xyz="0 0 0" rpy="0 0 0"/>
      <geometry><box size="0.08 0.08 0.02"/></geometry>
    </collision>
    <inertial>
      <origin xyz="0 0 0" rpy="0 0 0"/>
      <mass value="0.010"/>
      <inertia ixx="0.000011" ixy="0" ixz="0"
               iyy="0.000011" iyz="0"
               izz="0.000011"/>
    </inertial>
  </link>
  <joint name="lens_FR_joint" type="fixed">
    <parent link="payload"/>
    <child  link="lens_FR"/>
    <origin xyz="0.30 -0.35 0.05" rpy="0 0 0"/>
  </joint>

  <link name="lens_RL">
    <visual>
      <origin xyz="0 0 0" rpy="0 0 0"/>
      <geometry><box size="0.08 0.08 0.02"/></geometry>
      <material name="connector"/>
    </visual>
    <collision>
      <origin xyz="0 0 0" rpy="0 0 0"/>
      <geometry><box size="0.08 0.08 0.02"/></geometry>
    </collision>
    <inertial>
      <origin xyz="0 0 0" rpy="0 0 0"/>
      <mass value="0.010"/>
      <inertia ixx="0.000011" ixy="0" ixz="0"
               iyy="0.000011" iyz="0"
               izz="0.000011"/>
    </inertial>
  </link>
  <joint name="lens_RL_joint" type="fixed">
    <parent link="payload"/>
    <child  link="lens_RL"/>
    <origin xyz="-0.30 0.35 0.05" rpy="0 0 0"/>
  </joint>

  <link name="lens_RR">
    <visual>
      <origin xyz="0 0 0" rpy="0 0 0"/>
      <geometry><box size="0.08 0.08 0.02"/></geometry>
      <material name="connector"/>
    </visual>
    <collision>
      <origin xyz="0 0 0" rpy="0 0 0"/>
      <geometry><box size="0.08 0.08 0.02"/></geometry>
    </collision>
    <inertial>
      <origin xyz="0 0 0" rpy="0 0 0"/>
      <mass value="0.010"/>
      <inertia ixx="0.000011" ixy="0" ixz="0"
               iyy="0.000011" iyz="0"
               izz="0.000011"/>
    </inertial>
  </link>
  <joint name="lens_RR_joint" type="fixed">
    <parent link="payload"/>
    <child  link="lens_RR"/>
    <origin xyz="-0.30 -0.35 0.0500" rpy="0 0 0"/>
  </joint>

  <!-- 
       CIRCUIT SEGMENTS (4 total) — Connected loop around the 4 wheels
       
       LENS POSITIONS (at 4 corners - wheels attached here):
         • lens_FL: (+0.30, +0.35, 0.05) [Front-Left]
         • lens_FR: (+0.30, -0.35, 0.05) [Front-Right]
         • lens_RL: (-0.30, +0.35, 0.05) [Rear-Left]
         • lens_RR: (-0.30, -0.35, 0.05) [Rear-Right]
       
       SEGMENT CONNECTIONS (form rectangular circuit):
         • seg_front: FL → FR (0.70m along Y-axis)
         • seg_right: FR → RR (0.60m along X-axis)
         • seg_back: RR → RL (0.70m along Y-axis)
         • seg_left: RL → FL (0.60m along X-axis)
       
       EYELETS at segment midpoints (for tendon attachment):
         • eyelet_F: center of front segment
         • eyelet_R: center of right segment
         • eyelet_B: center of back segment
         • eyelet_L: center of left segment
 -->

  <!-- SEGMENT 1: FRONT  (0.70m Y-axis, FL → FR) -->
  <link name="seg_front">
    <visual>
      <origin xyz="0 0 0" rpy="1.5708 0 0"/>
      <geometry><cylinder radius="0.0025" length="0.70"/></geometry>
      <material name="fiberglass"/>
    </visual>
    <collision>
      <origin xyz="0 0 0" rpy="1.5708 0 0"/>
      <geometry><cylinder radius="0.0025" length="0.70"/></geometry>
    </collision>
    <inertial>
      <origin xyz="0 0 0" rpy="1.5708 0 0"/>
      <mass value="0.09"/>
      <inertia ixx="0.00000062" ixy="0" ixz="0"
               iyy="0.0029167" iyz="0"
               izz="0.0029167"/>
    </inertial>
  </link>
  <!-- Attach front segment to lens_FL, extends toward lens_FR -->
  <joint name="j_lens_FL_to_seg_front" type="fixed">
    <parent link="lens_FL"/>
    <child  link="seg_front"/>
    <origin xyz="0 0 0" rpy="0 0 0"/>
  </joint>

  <!-- EYELET F: midpoint of front segment -->
  <link name="eyelet_F">
    <visual>
      <origin xyz="0 0 0" rpy="0 0 0"/>
      <geometry><sphere radius="0.008"/></geometry>
      <material name="connector"/>
    </visual>
    <collision>
      <origin xyz="0 0 0" rpy="0 0 0"/>
      <geometry><sphere radius="0.008"/></geometry>
    </collision>
    <inertial>
      <origin xyz="0 0 0" rpy="0 0 0"/>
      <mass value="0.002"/>
      <inertia ixx="0.000001" ixy="0" ixz="0"
               iyy="0.000001" iyz="0"
               izz="0.000001"/>
    </inertial>
  </link>
  <joint name="j_seg_front_eyelet" type="fixed">
    <parent link="seg_front"/>
    <child  link="eyelet_F"/>
    <origin xyz="0 0 0" rpy="0 0 0"/>
  </joint>

  <!-- SEGMENT 2: RIGHT (0.60m X-axis, FR → RR) -->
  <link name="seg_right">
    <visual>
      <origin xyz="0 0 0" rpy="0 1.5708 0"/>
      <geometry><cylinder radius="0.0025" length="0.60"/></geometry>
      <material name="fiberglass"/>
    </visual>
    <collision>
      <origin xyz="0 0 0" rpy="0 1.5708 0"/>
      <geometry><cylinder radius="0.0025" length="0.60"/></geometry>
    </collision>
    <inertial>
      <origin xyz="0 0 0" rpy="0 1.5708 0"/>
      <mass value="0.08"/>
      <inertia ixx="0.00000062" ixy="0" ixz="0"
               iyy="0.0020000" iyz="0"
               izz="0.0020000"/>
    </inertial>
  </link>
  <!-- Attach right segment to lens_FR, extends toward lens_RR -->
  <joint name="j_lens_FR_to_seg_right" type="fixed">
    <parent link="lens_FR"/>
    <child  link="seg_right"/>
    <origin xyz="0 0 0" rpy="0 0 0"/>
  </joint>

  <!-- EYELET R: midpoint of right segment -->
  <link name="eyelet_R">
    <visual>
      <origin xyz="0 0 0" rpy="0 0 0"/>
      <geometry><sphere radius="0.008"/></geometry>
      <material name="connector"/>
    </visual>
    <collision>
      <origin xyz="0 0 0" rpy="0 0 0"/>
      <geometry><sphere radius="0.008"/></geometry>
    </collision>
    <inertial>
      <origin xyz="0 0 0" rpy="0 0 0"/>
      <mass value="0.002"/>
      <inertia ixx="0.000001" ixy="0" ixz="0"
               iyy="0.000001" iyz="0"
               izz="0.000001"/>
    </inertial>
  </link>
  <joint name="j_seg_right_eyelet" type="fixed">
    <parent link="seg_right"/>
    <child  link="eyelet_R"/>
    <origin xyz="0 0 0" rpy="0 0 0"/>
  </joint>

  <!-- SEGMENT 3: BACK (0.70m Y-axis, RR → RL) -->
  <link name="seg_back">
    <visual>
      <origin xyz="0 0 0" rpy="1.5708 0 0"/>
      <geometry><cylinder radius="0.0025" length="0.70"/></geometry>
      <material name="fiberglass"/>
    </visual>
    <collision>
      <origin xyz="0 0 0" rpy="1.5708 0 0"/>
      <geometry><cylinder radius="0.0025" length="0.70"/></geometry>
    </collision>
    <inertial>
      <origin xyz="0 0 0" rpy="1.5708 0 0"/>
      <mass value="0.09"/>
      <inertia ixx="0.00000062" ixy="0" ixz="0"
               iyy="0.0029167" iyz="0"
               izz="0.0029167"/>
    </inertial>
  </link>
  <!-- Attach back segment to lens_RR, extends toward lens_RL -->
  <joint name="j_lens_RR_to_seg_back" type="fixed">
    <parent link="lens_RR"/>
    <child  link="seg_back"/>
    <origin xyz="0 0 0" rpy="0 0 0"/>
  </joint>

  <!-- EYELET B: midpoint of back segment -->
  <link name="eyelet_B">
    <visual>
      <origin xyz="0 0 0" rpy="0 0 0"/>
      <geometry><sphere radius="0.008"/></geometry>
      <material name="connector"/>
    </visual>
    <collision>
      <origin xyz="0 0 0" rpy="0 0 0"/>
      <geometry><sphere radius="0.008"/></geometry>
    </collision>
    <inertial>
      <origin xyz="0 0 0" rpy="0 0 0"/>
      <mass value="0.002"/>
      <inertia ixx="0.000001" ixy="0" ixz="0"
               iyy="0.000001" iyz="0"
               izz="0.000001"/>
    </inertial>
  </link>
  <joint name="j_seg_back_eyelet" type="fixed">
    <parent link="seg_back"/>
    <child  link="eyelet_B"/>
    <origin xyz="0 0 0" rpy="0 0 0"/>
  </joint>

  <!-- SEGMENT 4: LEFT (0.60m X-axis, RL → FL) -->
  <link name="seg_left">
    <visual>
      <origin xyz="0 0 0" rpy="0 1.5708 0"/>
      <geometry><cylinder radius="0.0025" length="0.60"/></geometry>
      <material name="fiberglass"/>
    </visual>
    <collision>
      <origin xyz="0 0 0" rpy="0 1.5708 0"/>
      <geometry><cylinder radius="0.0025" length="0.60"/></geometry>
    </collision>
    <inertial>
      <origin xyz="0 0 0" rpy="0 1.5708 0"/>
      <mass value="0.08"/>
      <inertia ixx="0.00000062" ixy="0" ixz="0"
               iyy="0.0020000" iyz="0"
               izz="0.0020000"/>
    </inertial>
  </link>
  <!-- Attach left segment to lens_RL, extends toward lens_FL -->
  <joint name="j_lens_RL_to_seg_left" type="fixed">
    <parent link="lens_RL"/>
    <child  link="seg_left"/>
    <origin xyz="0 0 0" rpy="0 0 0"/>
  </joint>

  <!-- EYELET L: midpoint of left segment -->
  <link name="eyelet_L">
    <visual>
      <origin xyz="0 0 0" rpy="0 0 0"/>
      <geometry><sphere radius="0.008"/></geometry>
      <material name="connector"/>
    </visual>
    <collision>
      <origin xyz="0 0 0" rpy="0 0 0"/>
      <geometry><sphere radius="0.008"/></geometry>
    </collision>
    <inertial>
      <origin xyz="0 0 0" rpy="0 0 0"/>
      <mass value="0.002"/>
      <inertia ixx="0.000001" ixy="0" ixz="0"
               iyy="0.000001" iyz="0"
               izz="0.000001"/>
    </inertial>
  </link>
  <joint name="j_seg_left_eyelet" type="fixed">
    <parent link="seg_left"/>
    <child  link="eyelet_L"/>
    <origin xyz="0 0 0" rpy="0 0 0"/>
  </joint>

  <!-- 
       CIRCUIT CHAIN CONNECTIONS: Connect segments to form closed loop
       
       Each segment end connects to help form the rectangular circuit:
         seg_front end  ─→ point toward seg_right connection
         seg_right end  ─→ point toward seg_back connection
         seg_back end   ─→ point toward seg_left connection
         seg_left end   ─→ point back toward seg_front (loop closes via tendons)
  -->

  <!--
       WHEELS (×4) — Continuous joints at the 4 corners
       
       FL (Front-Left):   at (+0.30, +0.35, z_lens), spin on Y-axis
       FR (Front-Right):  at (+0.30, -0.35, z_lens), spin on X-axis
       RL (Rear-Left):    at (-0.30, +0.35, z_lens), spin on Y-axis
       RR (Rear-Right):   at (-0.30, -0.35, z_lens), spin on X-axis
       
       Radius: 0.25 m, mass: 0.05 kg each
 -->

  <link name="wheel_FL">
    <visual>
      <origin xyz="0 0 0" rpy="1.5708 0 0"/>
      <geometry><cylinder radius="0.2500" length="0.02"/></geometry>
      <material name="wheel_dark"/>
    </visual>
    <collision>
      <origin xyz="0 0 0" rpy="1.5708 0 0"/>
      <geometry><cylinder radius="0.2500" length="0.02"/></geometry>
    </collision>
    <inertial>
      <origin xyz="0 0 0" rpy="1.5708 0 0"/>
      <mass value="0.050"/>
      <inertia ixx="0.000800" ixy="0" ixz="0"
               iyy="0.001550" iyz="0"
               izz="0.000800"/>
    </inertial>
  </link>
  <joint name="wheel_FL_joint" type="continuous">
    <parent link="lens_FL"/>
    <child  link="wheel_FL"/>
    <origin xyz="0 0 0" rpy="0 0 0"/>
    <axis xyz="0 1 0"/>
    <dynamics damping="0.3" friction="0.05"/>
  </joint>

  <link name="wheel_FR">
    <visual>
      <origin xyz="0 0 0" rpy="1.5708 0 0"/>
      <geometry><cylinder radius="0.2500" length="0.02"/></geometry>
      <material name="wheel_dark"/>
    </visual>
    <collision>
      <origin xyz="0 0 0" rpy="1.5708 0 0"/>
      <geometry><cylinder radius="0.2500" length="0.02"/></geometry>
    </collision>
    <inertial>
      <origin xyz="0 0 0" rpy="1.5708 0 0"/>
      <mass value="0.050"/>
      <inertia ixx="0.001550" ixy="0" ixz="0"
               iyy="0.000800" iyz="0"
               izz="0.000800"/>
    </inertial>
  </link>
  <joint name="wheel_FR_joint" type="continuous">
    <parent link="lens_FR"/>
    <child  link="wheel_FR"/>
    <origin xyz="0 0 0" rpy="0 0 0"/>
    <axis xyz="1 0 0"/>
    <dynamics damping="0.3" friction="0.05"/>
  </joint>

  <link name="wheel_RL">
    <visual>
      <origin xyz="0 0 0" rpy="1.5708 0 0"/>
      <geometry><cylinder radius="0.2500" length="0.02"/></geometry>
      <material name="wheel_dark"/>
    </visual>
    <collision>
      <origin xyz="0 0 0" rpy="1.5708 0 0"/>
      <geometry><cylinder radius="0.2500" length="0.02"/></geometry>
    </collision>
    <inertial>
      <origin xyz="0 0 0" rpy="1.5708 0 0"/>
      <mass value="0.050"/>
      <inertia ixx="0.000800" ixy="0" ixz="0"
               iyy="0.001550" iyz="0"
               izz="0.000800"/>
    </inertial>
  </link>
  <joint name="wheel_RL_joint" type="continuous">
    <parent link="lens_RL"/>
    <child  link="wheel_RL"/>
    <origin xyz="0 0 0" rpy="0 0 0"/>
    <axis xyz="0 1 0"/>
    <dynamics damping="0.3" friction="0.05"/>
  </joint>

  <link name="wheel_RR">
    <visual>
      <origin xyz="0 0 0" rpy="1.5708 0 0"/>
      <geometry><cylinder radius="0.2500" length="0.02"/></geometry>
      <material name="wheel_dark"/>
    </visual>
    <collision>
      <origin xyz="0 0 0" rpy="1.5708 0 0"/>
      <geometry><cylinder radius="0.2500" length="0.02"/></geometry>
    </collision>
    <inertial>
      <origin xyz="0 0 0" rpy="1.5708 0 0"/>
      <mass value="0.050"/>
      <inertia ixx="0.001550" ixy="0" ixz="0"
               iyy="0.000800" iyz="0"
               izz="0.000800"/>
    </inertial>
  </link>
  <joint name="wheel_RR_joint" type="continuous">
    <parent link="lens_RR"/>
    <child  link="wheel_RR"/>
    <origin xyz="0 0 0" rpy="0 0 0"/>
    <axis xyz="1 0 0"/>
    <dynamics damping="0.3" friction="0.05"/>
  </joint>

  <!-- 
       TENDON SYSTEM (×2) — Virtual cables for morphing control
       
       Geometry:
         • Tendon 1 (horizontal X-axis): connects eyelet_L ← → eyelet_R
           - Passes along Y=+0.35 from X=-0 to X=+0
           - Controls left-right morphing deformation
         
         • Tendon 2 (vertical Y-axis): connects eyelet_F ← → eyelet_B  
           - Passes along X=+0.25 from Y=-0 to Y=+0
           - Controls front-back morphing deformation
       
       Both tendons attach to 4 eyelets (at segment midpoints) and pass through
       the center payload. When tendons contract, the circuit squeezes/morphs.
  -->

  <!-- TENDON CABLE 1: Visual link from Eyelet_L to Eyelet_R (X-axis) -->
  <link name="tendon_cable_1">
    <visual>
      <origin xyz="0 0 0" rpy="0 1.5708 0"/>
      <geometry><cylinder radius="0.0015" length="0.70"/></geometry>
      <material name="fiberglass"/>
    </visual>
    <collision>
      <origin xyz="0 0 0" rpy="0 1.5708 0"/>
      <geometry><cylinder radius="0.0015" length="0.70"/></geometry>
    </collision>
    <inertial>
      <origin xyz="0 0 0" rpy="0 1.5708 0"/>
      <mass value="0.003"/>
      <inertia ixx="0.00000010" ixy="0" ixz="0"
               iyy="0.00008750" iyz="0"
               izz="0.00008750"/>
    </inertial>
  </link>
  <!-- Fixed attachment to payload at origin, extends along X -->
  <joint name="j_payload_tendon_cable_1" type="fixed">
    <parent link="payload"/>
    <child  link="tendon_cable_1"/>
    <origin xyz="0 0 0" rpy="0 0 0"/>
  </joint>

  <!-- TENDON PRISMATIC JOINT 1: X-axis actuation for left-right morphing -->
  <link name="tendon_actuator_1">
    <inertial>
      <origin xyz="0 0 0" rpy="0 0 0"/>
      <mass value="0.001"/>
      <inertia ixx="0.000001" ixy="0" ixz="0"
               iyy="0.000001" iyz="0"
               izz="0.000001"/>
    </inertial>
  </link>
  <joint name="tendon_1" type="prismatic">
    <parent link="tendon_cable_1"/>
    <child  link="tendon_actuator_1"/>
    <origin xyz="0 0 0" rpy="0 0 0"/>
    <axis xyz="1 0 0"/>
    <limit lower="0.05" upper="0.50" effort="3.92" velocity="0.05"/>
    <dynamics damping="10.0" friction="0.5"/>
  </joint>

  <!-- TENDON CABLE 2: Visual link from Eyelet_F to Eyelet_B (Y-axis) -->
  <link name="tendon_cable_2">
    <visual>
      <origin xyz="0 0 0" rpy="1.5708 0 0"/>
      <geometry><cylinder radius="0.0015" length="0.60"/></geometry>
      <material name="fiberglass"/>
    </visual>
    <collision>
      <origin xyz="0 0 0" rpy="1.5708 0 0"/>
      <geometry><cylinder radius="0.0015" length="0.60"/></geometry>
    </collision>
    <inertial>
      <origin xyz="0 0 0" rpy="1.5708 0 0"/>
      <mass value="0.002"/>
      <inertia ixx="0.00000010" ixy="0" ixz="0"
               iyy="0.00005000" iyz="0"
               izz="0.00005000"/>
    </inertial>
  </link>
  <!-- Fixed attachment to payload at origin, extends along Y -->
  <joint name="j_payload_tendon_cable_2" type="fixed">
    <parent link="payload"/>
    <child  link="tendon_cable_2"/>
    <origin xyz="0 0 0" rpy="0 0 0"/>
  </joint>

  <!-- TENDON PRISMATIC JOINT 2: Y-axis actuation for front-back morphing -->
  <link name="tendon_actuator_2">
    <inertial>
      <origin xyz="0 0 0" rpy="0 0 0"/>
      <mass value="0.001"/>
      <inertia ixx="0.000001" ixy="0" ixz="0"
               iyy="0.000001" iyz="0"
               izz="0.000001"/>
    </inertial>
  </link>
  <joint name="tendon_2" type="prismatic">
    <parent link="tendon_cable_2"/>
    <child  link="tendon_actuator_2"/>
    <origin xyz="0 0 0" rpy="0 0 0"/>
    <axis xyz="0 1 0"/>
    <limit lower="0.05" upper="0.50" effort="3.92" velocity="0.05"/>
    <dynamics damping="10.0" friction="0.5"/>
  </joint>

</robot>